2025-03-13 16:51:50,386 - INFO - Iniciando o BOT-ALEXO Versão:0.1.3
2025-03-13 16:51:51,761 - INFO - Bot está rodando...
2025-03-13 16:51:58,132 - ERROR - No error handlers are registered, logging exception.
Traceback (most recent call last):
  File "telegram\ext\_utils\networkloop.py", line 115, in network_retry_loop
  File "telegram\ext\_utils\networkloop.py", line 108, in do_action
  File "telegram\ext\_updater.py", line 376, in polling_action_cb
  File "telegram\ext\_extbot.py", line 658, in get_updates
  File "telegram\_bot.py", line 4605, in get_updates
  File "telegram\_bot.py", line 691, in _post
  File "telegram\ext\_extbot.py", line 362, in _do_post
  File "telegram\_bot.py", line 720, in _do_post
  File "telegram\request\_baserequest.py", line 202, in post
  File "telegram\request\_baserequest.py", line 385, in _request_wrapper
telegram.error.Conflict: Conflict: terminated by other getUpdates request; make sure that only one bot instance is running
2025-03-13 16:52:04,086 - ERROR - No error handlers are registered, logging exception.
Traceback (most recent call last):
  File "telegram\ext\_utils\networkloop.py", line 115, in network_retry_loop
  File "telegram\ext\_utils\networkloop.py", line 108, in do_action
  File "telegram\ext\_updater.py", line 376, in polling_action_cb
  File "telegram\ext\_extbot.py", line 658, in get_updates
  File "telegram\_bot.py", line 4605, in get_updates
  File "telegram\_bot.py", line 691, in _post
  File "telegram\ext\_extbot.py", line 362, in _do_post
  File "telegram\_bot.py", line 720, in _do_post
  File "telegram\request\_baserequest.py", line 202, in post
  File "telegram\request\_baserequest.py", line 385, in _request_wrapper
telegram.error.Conflict: Conflict: terminated by other getUpdates request; make sure that only one bot instance is running
2025-03-13 16:52:09,518 - ERROR - No error handlers are registered, logging exception.
Traceback (most recent call last):
  File "telegram\ext\_utils\networkloop.py", line 115, in network_retry_loop
  File "telegram\ext\_utils\networkloop.py", line 108, in do_action
  File "telegram\ext\_updater.py", line 376, in polling_action_cb
  File "telegram\ext\_extbot.py", line 658, in get_updates
  File "telegram\_bot.py", line 4605, in get_updates
  File "telegram\_bot.py", line 691, in _post
  File "telegram\ext\_extbot.py", line 362, in _do_post
  File "telegram\_bot.py", line 720, in _do_post
  File "telegram\request\_baserequest.py", line 202, in post
  File "telegram\request\_baserequest.py", line 385, in _request_wrapper
telegram.error.Conflict: Conflict: terminated by other getUpdates request; make sure that only one bot instance is running
2025-03-13 16:52:15,552 - ERROR - No error handlers are registered, logging exception.
Traceback (most recent call last):
  File "telegram\ext\_utils\networkloop.py", line 115, in network_retry_loop
  File "telegram\ext\_utils\networkloop.py", line 108, in do_action
  File "telegram\ext\_updater.py", line 376, in polling_action_cb
  File "telegram\ext\_extbot.py", line 658, in get_updates
  File "telegram\_bot.py", line 4605, in get_updates
  File "telegram\_bot.py", line 691, in _post
  File "telegram\ext\_extbot.py", line 362, in _do_post
  File "telegram\_bot.py", line 720, in _do_post
  File "telegram\request\_baserequest.py", line 202, in post
  File "telegram\request\_baserequest.py", line 385, in _request_wrapper
telegram.error.Conflict: Conflict: terminated by other getUpdates request; make sure that only one bot instance is running
2025-03-13 16:52:22,686 - ERROR - No error handlers are registered, logging exception.
Traceback (most recent call last):
  File "telegram\ext\_utils\networkloop.py", line 115, in network_retry_loop
  File "telegram\ext\_utils\networkloop.py", line 108, in do_action
  File "telegram\ext\_updater.py", line 376, in polling_action_cb
  File "telegram\ext\_extbot.py", line 658, in get_updates
  File "telegram\_bot.py", line 4605, in get_updates
  File "telegram\_bot.py", line 691, in _post
  File "telegram\ext\_extbot.py", line 362, in _do_post
  File "telegram\_bot.py", line 720, in _do_post
  File "telegram\request\_baserequest.py", line 202, in post
  File "telegram\request\_baserequest.py", line 385, in _request_wrapper
telegram.error.Conflict: Conflict: terminated by other getUpdates request; make sure that only one bot instance is running
2025-03-13 16:52:29,464 - ERROR - No error handlers are registered, logging exception.
Traceback (most recent call last):
  File "telegram\ext\_utils\networkloop.py", line 115, in network_retry_loop
  File "telegram\ext\_utils\networkloop.py", line 108, in do_action
  File "telegram\ext\_updater.py", line 376, in polling_action_cb
  File "telegram\ext\_extbot.py", line 658, in get_updates
  File "telegram\_bot.py", line 4605, in get_updates
  File "telegram\_bot.py", line 691, in _post
  File "telegram\ext\_extbot.py", line 362, in _do_post
  File "telegram\_bot.py", line 720, in _do_post
  File "telegram\request\_baserequest.py", line 202, in post
  File "telegram\request\_baserequest.py", line 385, in _request_wrapper
telegram.error.Conflict: Conflict: terminated by other getUpdates request; make sure that only one bot instance is running
2025-03-13 16:56:24,984 - INFO - Iniciando o BOT-ALEXO Versão:0.1.3
2025-03-13 16:56:26,377 - INFO - Bot está rodando...
2025-03-13 16:56:32,831 - ERROR - No error handlers are registered, logging exception.
Traceback (most recent call last):
  File "telegram\ext\_utils\networkloop.py", line 115, in network_retry_loop
  File "telegram\ext\_utils\networkloop.py", line 108, in do_action
  File "telegram\ext\_updater.py", line 376, in polling_action_cb
  File "telegram\ext\_extbot.py", line 658, in get_updates
  File "telegram\_bot.py", line 4605, in get_updates
  File "telegram\_bot.py", line 691, in _post
  File "telegram\ext\_extbot.py", line 362, in _do_post
  File "telegram\_bot.py", line 720, in _do_post
  File "telegram\request\_baserequest.py", line 202, in post
  File "telegram\request\_baserequest.py", line 385, in _request_wrapper
telegram.error.Conflict: Conflict: terminated by other getUpdates request; make sure that only one bot instance is running
2025-03-13 17:47:55,931 - INFO - Iniciando o BOT-ALEXO Versão:0.1.3
2025-03-13 17:47:57,233 - INFO - Bot está rodando...
2025-03-13 17:48:16,503 - INFO - Iniciando o BOT-ALEXO Versão:0.1.3
2025-03-13 17:48:17,760 - INFO - Bot está rodando...
2025-03-13 17:51:20,043 - INFO - Iniciando o BOT-ALEXO Versão:0.1.3
2025-03-13 17:51:21,333 - INFO - Bot está rodando...
2025-03-13 17:51:58,124 - INFO - Iniciando o BOT-ALEXO Versão:0.1.3
2025-03-13 17:51:59,407 - INFO - Bot está rodando...
2025-03-13 17:53:33,305 - INFO - Iniciando o BOT-ALEXO Versão:0.1.3
2025-03-13 17:53:34,678 - INFO - Bot está rodando...
2025-03-13 17:53:56,880 - INFO - Iniciando o BOT-ALEXO Versão:0.1.3
2025-03-13 17:53:58,141 - INFO - Bot está rodando...
2025-03-13 17:57:56,315 - INFO - Iniciando o BOT-ALEXO Versão:0.1.3
2025-03-13 17:57:57,631 - INFO - Bot está rodando...
2025-03-13 17:59:48,509 - INFO - Iniciando o BOT-ALEXO Versão:0.1.3
2025-03-13 17:59:49,939 - INFO - Bot está rodando...
2025-03-13 18:04:29,777 - INFO - Iniciando o BOT-ALEXO Versão:0.1.3
2025-03-13 18:04:31,051 - INFO - Bot está rodando...
2025-03-13 18:06:18,037 - INFO - Iniciando o BOT-ALEXO Versão:0.1.3
2025-03-13 18:06:19,428 - INFO - Bot está rodando...
2025-03-13 18:10:21,363 - INFO - Iniciando o BOT-ALEXO Versão:0.1.3
2025-03-13 18:10:22,687 - INFO - Bot está rodando...
